Workbook

Sheet Overview
A1: Sum of Weights | B1: Maximum Possible Score | C1: Calculated Weighted Average Score | D1: Difference from Maximum Score
A2: =SUM(Scoring!E2:E140) -> 0 | B2: 10 | C2: =SUM(Scoring!H2:H140)/A2 -> 0 | D2: =B2-C2 -> 0
A4: Domain | B4: Action Count
A5: Manage the FinOps Practice | B5: 42 | U5: =SUMIF(Scoring!I2:I140,A5,Scoring!H2:H140)/SUMIF(Scoring!I2:I140,A5,Scoring!E2:E140) -> 0
A6: Optimize Usage & Cost | B6: 36 | U6: =SUMIF(Scoring!I2:I140,A6,Scoring!H2:H140)/SUMIF(Scoring!I2:I140,A6,Scoring!E2:E140) -> 0
A7: Quantify Business Value | B7: 31 | U7: =SUMIF(Scoring!I2:I140,A7,Scoring!H2:H140)/SUMIF(Scoring!I2:I140,A7,Scoring!E2:E140) -> 0
A8: Understand Usage & Cost | B8: 30 | U8: =SUMIF(Scoring!I2:I140,A8,Scoring!H2:H140)/SUMIF(Scoring!I2:I140,A8,Scoring!E2:E140) -> 0
B9: =SUM(Overview!$B$5:$B$8) -> 0
A11: Capability | B11: Action Count
A12: Allocation | B12: 7 | U12: =SUMIF(Scoring!J2:J140,A12,Scoring!H2:H140)/SUMIF(Scoring!J2:J140,A12,Scoring!E2:E140) -> 0
A13: Anomaly Management | B13: 7 | U13: =SUMIF(Scoring!J2:J140,A13,Scoring!H2:H140)/SUMIF(Scoring!J2:J140,A13,Scoring!E2:E140) -> 0
A14: Architecting & Workload Placement | B14: 12 | U14: =SUMIF(Scoring!J2:J140,A14,Scoring!H2:H140)/SUMIF(Scoring!J2:J140,A14,Scoring!E2:E140) -> 0
A15: Automation, Tools & Services | B15: 5 | U15: =SUMIF(Scoring!J2:J140,A15,Scoring!H2:H140)/SUMIF(Scoring!J2:J140,A15,Scoring!E2:E140) -> 0
A16: Budgeting | B16: 6 | U16: =SUMIF(Scoring!J2:J140,A16,Scoring!H2:H140)/SUMIF(Scoring!J2:J140,A16,Scoring!E2:E140) -> 0
A17: Data Ingestion | B17: 9 | U17: =SUMIF(Scoring!J2:J140,A17,Scoring!H2:H140)/SUMIF(Scoring!J2:J140,A17,Scoring!E2:E140) -> 0
A18: Executive Strategy Alignment | B18: 4 | U18: =SUMIF(Scoring!J2:J140,A18,Scoring!H2:H140)/SUMIF(Scoring!J2:J140,A18,Scoring!E2:E140) -> 0
A19: FinOps Assessment | B19: 5 | U19: =SUMIF(Scoring!J2:J140,A19,Scoring!H2:H140)/SUMIF(Scoring!J2:J140,A19,Scoring!E2:E140) -> 0
A20: FinOps Education & Enablement | B20: 5 | U20: =SUMIF(Scoring!J2:J140,A20,Scoring!H2:H140)/SUMIF(Scoring!J2:J140,A20,Scoring!E2:E140) -> 0
A21: FinOps Practice Operations | B21: 6 | U21: =SUMIF(Scoring!J2:J140,A21,Scoring!H2:H140)/SUMIF(Scoring!J2:J140,A21,Scoring!E2:E140) -> 0
A22: Forecasting | B22: 6 | U22: =SUMIF(Scoring!J2:J140,A22,Scoring!H2:H140)/SUMIF(Scoring!J2:J140,A22,Scoring!E2:E140) -> 0
A23: Governance, Policy & Risk | B23: 5 | U23: =SUMIF(Scoring!J2:J140,A23,Scoring!H2:H140)/SUMIF(Scoring!J2:J140,A23,Scoring!E2:E140) -> 0
A24: Intersecting Disciplines | B24: 6 | U24: =SUMIF(Scoring!J2:J140,A24,Scoring!H2:H140)/SUMIF(Scoring!J2:J140,A24,Scoring!E2:E140) -> 0
A25: Invoicing & Chargeback | B25: 6 | U25: =SUMIF(Scoring!J2:J140,A25,Scoring!H2:H140)/SUMIF(Scoring!J2:J140,A25,Scoring!E2:E140) -> 0
A26: KPIs & Benchmarking | B26: 6 | U26: =SUMIF(Scoring!J2:J140,A26,Scoring!H2:H140)/SUMIF(Scoring!J2:J140,A26,Scoring!E2:E140) -> 0
A27: Licensing & SaaS | B27: 6 | U27: =SUMIF(Scoring!J2:J140,A27,Scoring!H2:H140)/SUMIF(Scoring!J2:J140,A27,Scoring!E2:E140) -> 0
A28: Planning & Estimating | B28: 7 | U28: =SUMIF(Scoring!J2:J140,A28,Scoring!H2:H140)/SUMIF(Scoring!J2:J140,A28,Scoring!E2:E140) -> 0
A29: Rate Optimization | B29: 6 | U29: =SUMIF(Scoring!J2:J140,A29,Scoring!H2:H140)/SUMIF(Scoring!J2:J140,A29,Scoring!E2:E140) -> 0
A30: Reporting & Analytics | B30: 7 | U30: =SUMIF(Scoring!J2:J140,A30,Scoring!H2:H140)/SUMIF(Scoring!J2:J140,A30,Scoring!E2:E140) -> 0
A31: Sustainability | B31: 6 | U31: =SUMIF(Scoring!J2:J140,A31,Scoring!H2:H140)/SUMIF(Scoring!J2:J140,A31,Scoring!E2:E140) -> 0
A32: Unit Economics | B32: 6 | U32: =SUMIF(Scoring!J2:J140,A32,Scoring!H2:H140)/SUMIF(Scoring!J2:J140,A32,Scoring!E2:E140) -> 0
A33: Usage Optimization | B33: 6 | U33: =SUMIF(Scoring!J2:J140,A33,Scoring!H2:H140)/SUMIF(Scoring!J2:J140,A33,Scoring!E2:E140) -> 0
B34: =SUM(Overview!$B$12:$B$33) -> 0

Sheet Scoring
A1: domain | B1: capability | C1: action | D1: serial number | E1: weights | F1: formula | G1: scoring | H1: weighted score | I1: _domain | J1: _capability
A2: Understand Usage & Cost | B2: Data Ingestion | C2: Inventory All Data Sources | D2: 001 | E2: 0 | G2: 0: None | H2: =E2*VALUE(LEFT(G2, FIND(":", G2)-1)) -> 0 | I2: Understand Usage & Cost | J2: Data Ingestion
C3: Choose Data Landing Tooling | D3: 002 | E3: 0 | G3: 0: None | H3: =E3*VALUE(LEFT(G3, FIND(":", G3)-1)) -> 0 | I3: Understand Usage & Cost | J3: Data Ingestion
C4: Create Landing Zones & Controls | D4: 003 | E4: 0 | G4: 0: None | H4: =E4*VALUE(LEFT(G4, FIND(":", G4)-1)) -> 0 | I4: Understand Usage & Cost | J4: Data Ingestion
C5: Define Data Granularity & Frequency | D5: 004 | E5: 1 | G5: 0: Never | H5: =E5*VALUE(LEFT(G5, FIND(":", G5)-1)) -> 0 | I5: Understand Usage & Cost | J5: Data Ingestion
C6: Document Normalization Rules | D6: 005 | E6: 0 | G6: 0: None | H6: =E6*VALUE(LEFT(G6, FIND(":", G6)-1)) -> 0 | I6: Understand Usage & Cost | J6: Data Ingestion
C7: Implement Data Quality Checks | D7: 006 | E7: 1 | F7: * Define data quality (complete, valid, etc.) * Manual quality checks * Automated checks (null % on required fields/tags) * Response process and triage defined * SLAs defined and monitored * Integrate with communication and alerting tools * Integrate into CI/CD pipelines 10*Ceil(x/7) | G7: 0: No items completed | H7: =E7*VALUE(LEFT(G7, FIND(":", G7)-1)) -> 0 | I7: Understand Usage & Cost | J7: Data Ingestion
C8: Build Ingestion Anomaly Dashboards | D8: 007 | E8: 1 | F8: Not in order, gain points for each task * Manual or basic logs * Define key metrics (failures, latency, etc.) * Static Dashboard updated manually * Automated alerts for failures * Integrate with communication and alerting tools * Define Process & SLAs:RCAs completed for each * Tune out false positives 10*Ceil(x/7) | G8: 0: No items completed | H8: =E8*VALUE(LEFT(G8, FIND(":", G8)-1)) -> 0 | I8: Understand Usage & Cost | J8: Data Ingestion
C9: Optimize Pipelines for Timeliness | D9: 008 | E9: 0 | G9: 0: None | H9: =E9*VALUE(LEFT(G9, FIND(":", G9)-1)) -> 0 | I9: Understand Usage & Cost | J9: Data Ingestion
C10: Define ingestion frequency; include mandatory metadata. | D10: 135 | E10: 1 | G10: 0: Never | H10: =E10*VALUE(LEFT(G10, FIND(":", G10)-1)) -> 0 | I10: Understand Usage & Cost | J10: Data Ingestion
B11: Allocation | C11: Define Metadata & Hierarchy Strategy | D11: 009 | E11: 1 | F11: Increasing Granularity and Visibility * Define metadata to track (org, dept, cost center, team, app, etc.) * Create the hierarchy for each category of metadata (ex teams per dept, cost centers in an org) 10*Ceil(x/2) | G11: 0: No items completed | H11: =E11*VALUE(LEFT(G11, FIND(":", G11)-1)) -> 0 | I11: Understand Usage & Cost | J11: Allocation
C12: Identify Shared Costs & Rules | D12: 010 | E12: 1 | F12: Unallocated Shared CSP Effective Cloud Cost/ Total CSP Effective Cloud Cost | G12: 0: 0% | H12: =E12*VALUE(LEFT(G12, FIND(":", G12)-1)) -> 0 | I12: Understand Usage & Cost | J12: Allocation
C13: Publish Allocation Taxonomy | D13: 011 | E13: 1 | F13: Increasing Granularity and Visibility * Document as part of tagging strategy and enforcement * Teams have visibility into where their resources fit into the hierarchy 10*Ceil(x/2) | G13: 0: No items completed | H13: =E13*VALUE(LEFT(G13, FIND(":", G13)-1)) -> 0 | I13: Understand Usage & Cost | J13: Allocation
C14: Implement Tagging Standards | D14: 012 | E14: 1 | F14: Percentage of total costs that are tagged for Each Required Tag | G14: 0: 0% | H14: =E14*VALUE(LEFT(G14, FIND(":", G14)-1)) -> 0 | I14: Understand Usage & Cost | J14: Allocation
C15: Validate Compliance & Report Gaps | D15: 013 | E15: 1 | F15: x = Total Effective Costs Associated with Unallocated CSP Cloud Resources During y = Total CSP Cloud Costs During a Period of Time x / y | G15: 0: 0% | H15: =E15*VALUE(LEFT(G15, FIND(":", G15)-1)) -> 0 | I15: Understand Usage & Cost | J15: Allocation
C16: Automate Tagging & Enforcement | D16: 014 | E16: 1 | F16: Effectiveness/Effort by strategy * Manually asking teams to tag resources * Remove untagged resources after time threshold * Block deployments without proper tags * Automatically tag based on CI/CD creator and team 10*Ceil(x/4) | G16: 0: No items completed | H16: =E16*VALUE(LEFT(G16, FIND(":", G16)-1)) -> 0 | I16: Understand Usage & Cost | J16: Allocation
C17: Iterate Strategies & Communicate | D17: 015 | E17: 0 | G17: 0: None | H17: =E17*VALUE(LEFT(G17, FIND(":", G17)-1)) -> 0 | I17: Understand Usage & Cost | J17: Allocation
B18: Reporting & Analytics | C18: Gather Requirements & Define KPIs | D18: 016 | E18: 0 | G18: 0: None | H18: =E18*VALUE(LEFT(G18, FIND(":", G18)-1)) -> 0 | I18: Understand Usage & Cost | J18: Reporting & Analytics
C19: Enrich Billing with Business Logic | D19: 017 | E19: 1 | F19: * Manual adjustments to invoices and teams * Define Business Rules for sharing discounts, RI/SP, etc. * Automate adjustment calculations monthly in arrears * Automate mappings into reporting platform for realtime adjustments 10*Ceil(x/4) | G19: 0: No items completed | H19: =E19*VALUE(LEFT(G19, FIND(":", G19)-1)) -> 0 | I19: Understand Usage & Cost | J19: Reporting & Analytics
C20: Build Dashboards for All Views | D20: 018 | E20: 1 | F20: * Dashboard for showback * Dashboard where teams can dive in to investigate costs * Ad-hoc dashboards available to teams * Dashboards for key metrics tracking (tagging, waste, etc.) 10*Ceil(x/4) | G20: 0: No items completed | H20: =E20*VALUE(LEFT(G20, FIND(":", G20)-1)) -> 0 | I20: Understand Usage & Cost | J20: Reporting & Analytics
C21: Publish Documentation & Support | D21: 019 | E21: 0 | G21: 0: None | H21: =E21*VALUE(LEFT(G21, FIND(":", G21)-1)) -> 0 | I21: Understand Usage & Cost | J21: Reporting & Analytics
C22: Embed Reports in Workflows | D22: 020 | E22: 1 | G22: 0: No alerting in workflow tools | H22: =E22*VALUE(LEFT(G22, FIND(":", G22)-1)) -> 0 | I22: Understand Usage & Cost | J22: Reporting & Analytics
C23: Track Adoption & Manage Changes | D23: 021 | E23: 0 | G23: 0: None | H23: =E23*VALUE(LEFT(G23, FIND(":", G23)-1)) -> 0 | I23: Understand Usage & Cost | J23: Reporting & Analytics
C24: Iterate Based on Feedback | D24: 022 | E24: 0 | G24: 0: None | H24: =E24*VALUE(LEFT(G24, FIND(":", G24)-1)) -> 0 | I24: Understand Usage & Cost | J24: Reporting & Analytics
B25: Anomaly Management | C25: Configure Cost Spike Detection | D25: 023 | E25: 1 | F25: * Manual inspection of spikes * Out-of-the-box tool based anomaly alerts * Custom simple increase alert calculations * Custom alerts per business unit, team, etc. * Alerts per unit costs above thresholds 10*Ceil(x/5) | G25: 0: No items completed | H25: =E25*VALUE(LEFT(G25, FIND(":", G25)-1)) -> 0 | I25: Understand Usage & Cost | J25: Anomaly Management
C26: Define Severity & Response SLAs | D26: 024 | E26: 1 | F26: * Defined severity tiers * Thresholds associated with severity tiers are defined * Defined and adhered to response SLAs * Published response runbooks * Runbook percent successful or completed * RCA completed after alerts 10*Ceil(x/6) | G26: 0: No items completed | H26: =E26*VALUE(LEFT(G26, FIND(":", G26)-1)) -> 0 | I26: Understand Usage & Cost | J26: Anomaly Management
C27: Automate Alert Routing | D27: 025 | E27: 1 | G27: 0: No alerting to any owners | H27: =E27*VALUE(LEFT(G27, FIND(":", G27)-1)) -> 0 | I27: Understand Usage & Cost | J27: Anomaly Management
C28: Record Anomaly Context & Timeline | D28: 026 | E28: 0 | G28: 0: None | H28: =E28*VALUE(LEFT(G28, FIND(":", G28)-1)) -> 0 | I28: Understand Usage & Cost | J28: Anomaly Management
C29: Analyze Root Causes & Fix Issues | D29: 027 | E29: 0 | G29: 0: None | H29: =E29*VALUE(LEFT(G29, FIND(":", G29)-1)) -> 0 | I29: Understand Usage & Cost | J29: Anomaly Management
C30: Track Metrics & Avoidance Rates | D30: 028 | E30: 1 | F30: * Number of detections per time period * Number of detections over threshold * Time to send notifications to stakeholders * Time to validate anomaly * Resolution Time/SLA adherence * False positive rate * Cost Avoidance due to detection * Percent anomalies addressed 10*Ceil(x/8) | G30: 0: No items completed | H30: =E30*VALUE(LEFT(G30, FIND(":", G30)-1)) -> 0 | I30: Understand Usage & Cost | J30: Anomaly Management
C31: Tune Thresholds to Reduce Noise | D31: 029 | E31: 0 | G31: 0: None | H31: =E31*VALUE(LEFT(G31, FIND(":", G31)-1)) -> 0 | I31: Understand Usage & Cost | J31: Anomaly Management
A32: Quantify Business Value | B32: Planning & Estimating | C32: Define Estimating Scope & Policy | D32: 030 | E32: 1 | F32: * Defined scope of each project to be estimated * Developed list of known inputs to the project * Have a process to determine what may be missing from the inputs or scope * Have a policy review to determine additional needs for inputs or scope * For each component of the estimate, list all assumptions 10*Ceil(x/5) | G32: 0: No items completed | H32: =E32*VALUE(LEFT(G32, FIND(":", G32)-1)) -> 0 | I32: Quantify Business Value | J32: Planning & Estimating
C33: Agree on Pricing Assumptions | D33: 031 | E33: 1 | F33: * Inventory possible commitment based discounts (RIs, Savings Plans, CUDs, etc.) available for deployed resources * Consider any private negotiated line item discounts vs public RI/CUD discounts * Set resource type standards to make use of spend commitments while maintaining needs of the business * Scenario plan commitment options versus potential changes in resources * Reference commit allocation strategy to calculate cost impact of shared scope vs private account commitments 10*Ceil(x/5) | G33: 0: No items completed | H33: =E33*VALUE(LEFT(G33, FIND(":", G33)-1)) -> 0 | I33: Quantify Business Value | J33: Planning & Estimating
C34: Select Estimation Methods | D34: 032 | E34: 1 | F34: * Use pricing lists or pricing calculators to estimate workload spend * Run workloads as trial experiments to get baseline spend * Estimate workload costs based on similar applications already deployed in your environment * Determine fixed costs vs formulas for variable costs due to growth of workloads * Factor in discounts and uptime metrics to determine accurate spend vs list 10*Ceil(x/5) | G34: 0: No items completed | H34: =E34*VALUE(LEFT(G34, FIND(":", G34)-1)) -> 0 | I34: Quantify Business Value | J34: Planning & Estimating
C35: Include Sustainability Impacts | D35: 033 | E35: 1 | F35: 1. Calculate kg of carbon dioxide equivalents (kgCO2e), or similar, for new and ongoing workloads 2. Compare carbon calculations with targets for new projects and overall consumption | G35: 0: No items completed | H35: =E35*VALUE(LEFT(G35, FIND(":", G35)-1)) -> 0 | I35: Quantify Business Value | J35: Planning & Estimating
C36: Establish Scenario Decision Process | D36: 034 | E36: 1 | F36: * Define and follow process for gathering deployment plans from teams * Determine timeline for each new project to adjust the forecast during that time * Determine how optimizations and lower run rate will impact the forecast on a rolling basis 10*Ceil(x/3) | G36: 0: No items completed | H36: =E36*VALUE(LEFT(G36, FIND(":", G36)-1)) -> 0 | I36: Quantify Business Value | J36: Planning & Estimating
C37: Report Estimate Accuracy | D37: 035 | E37: 1 | G37: 0: 0% | H37: =E37*VALUE(LEFT(G37, FIND(":", G37)-1)) -> 0 | I37: Quantify Business Value | J37: Planning & Estimating
C38: Coach Engineering on Estimates | D38: 036 | E38: 1 | F38: * Refer teams to Documented Estimating Scope & Policy and include these methods in trainings * Teams track baseline spend for resources they own, and share changes to baseline with leadership * Teams will share updates about their change in usage of shared resources and dependencies * Track team adoption of better estimates via KPIs around baseline or plan vs actuals 10*Ceil(x/4) | G38: 0: No items completed | H38: =E38*VALUE(LEFT(G38, FIND(":", G38)-1)) -> 0 | I38: Quantify Business Value | J38: Planning & Estimating
B39: Forecasting | C39: Establish Forecasting Approach | D39: 037 | E39: 0 | G39: 0: None | H39: =E39*VALUE(LEFT(G39, FIND(":", G39)-1)) -> 0 | I39: Quantify Business Value | J39: Forecasting
C40: Collect Business Drivers Regularly | D40: 038 | E40: 1 | F40: * Data based on existing patterns * Proactive investigations and interviews with teams * Proactive self reporting by the business and/or teams * 100% catch rate of spikes before they happen 10*Ceil(x/4) | G40: 0: No items completed | H40: =E40*VALUE(LEFT(G40, FIND(":", G40)-1)) -> 0 | I40: Quantify Business Value | J40: Forecasting
...
