Workbook

Sheet Overview
A1: Sum of Weights | B1: Maximum Possible Score | C1: Calculated Weighted Average Score | D1: Difference from Maximum Score
A2: =SUM(Scoring!F2:F134) -> 0 | B2: 10 | C2: =SUM(Scoring!I2:I134)/A2 -> 0 | D2: =B2-C2 -> 0
A4: Domain | B4: Action Count
A5: Governance | B5: 5 | U5: =SUMIF(Scoring!J2:J134,A5,Scoring!I2:I134)/SUMIF(Scoring!J2:J134,A5,Scoring!F2:F134) -> 0
A6: Manage the FinOps Practice | B6: 37 | U6: =SUMIF(Scoring!J2:J134,A6,Scoring!I2:I134)/SUMIF(Scoring!J2:J134,A6,Scoring!F2:F134) -> 0
A7: Quantify Business Value | B7: 31 | U7: =SUMIF(Scoring!J2:J134,A7,Scoring!I2:I134)/SUMIF(Scoring!J2:J134,A7,Scoring!F2:F134) -> 0
A8: Usage & Cost | B8: 60 | U8: =SUMIF(Scoring!J2:J134,A8,Scoring!I2:I134)/SUMIF(Scoring!J2:J134,A8,Scoring!F2:F134) -> 0
B9: =SUM(Overview!$B$5:$B$8) -> 0
A11: Capability | B11: Action Count
A12: Allocation | B12: 7 | U12: =SUMIF(Scoring!K2:K134,A12,Scoring!I2:I134)/SUMIF(Scoring!K2:K134,A12,Scoring!F2:F134) -> 0
A13: Anomaly Management | B13: 7 | U13: =SUMIF(Scoring!K2:K134,A13,Scoring!I2:I134)/SUMIF(Scoring!K2:K134,A13,Scoring!F2:F134) -> 0
A14: Architecting & Workload Placement | B14: 12 | U14: =SUMIF(Scoring!K2:K134,A14,Scoring!I2:I134)/SUMIF(Scoring!K2:K134,A14,Scoring!F2:F134) -> 0
A15: Automation, Tools & Services | B15: 5 | U15: =SUMIF(Scoring!K2:K134,A15,Scoring!I2:I134)/SUMIF(Scoring!K2:K134,A15,Scoring!F2:F134) -> 0
A16: Budgeting | B16: 6 | U16: =SUMIF(Scoring!K2:K134,A16,Scoring!I2:I134)/SUMIF(Scoring!K2:K134,A16,Scoring!F2:F134) -> 0
A17: Data Ingestion | B17: 9 | U17: =SUMIF(Scoring!K2:K134,A17,Scoring!I2:I134)/SUMIF(Scoring!K2:K134,A17,Scoring!F2:F134) -> 0
A18: Executive Strategy Alignment | B18: 4 | U18: =SUMIF(Scoring!K2:K134,A18,Scoring!I2:I134)/SUMIF(Scoring!K2:K134,A18,Scoring!F2:F134) -> 0
A19: FinOps Assessment | B19: 5 | U19: =SUMIF(Scoring!K2:K134,A19,Scoring!I2:I134)/SUMIF(Scoring!K2:K134,A19,Scoring!F2:F134) -> 0
A20: FinOps Education & Enablement | B20: 5 | U20: =SUMIF(Scoring!K2:K134,A20,Scoring!I2:I134)/SUMIF(Scoring!K2:K134,A20,Scoring!F2:F134) -> 0
A21: FinOps Practice Operations | B21: 6 | U21: =SUMIF(Scoring!K2:K134,A21,Scoring!I2:I134)/SUMIF(Scoring!K2:K134,A21,Scoring!F2:F134) -> 0
A22: Forecasting | B22: 6 | U22: =SUMIF(Scoring!K2:K134,A22,Scoring!I2:I134)/SUMIF(Scoring!K2:K134,A22,Scoring!F2:F134) -> 0
A23: Intersecting Disciplines | B23: 6 | U23: =SUMIF(Scoring!K2:K134,A23,Scoring!I2:I134)/SUMIF(Scoring!K2:K134,A23,Scoring!F2:F134) -> 0
A24: Invoicing & Chargeback | B24: 6 | U24: =SUMIF(Scoring!K2:K134,A24,Scoring!I2:I134)/SUMIF(Scoring!K2:K134,A24,Scoring!F2:F134) -> 0
A25: KPIs & Benchmarking | B25: 6 | U25: =SUMIF(Scoring!K2:K134,A25,Scoring!I2:I134)/SUMIF(Scoring!K2:K134,A25,Scoring!F2:F134) -> 0
A26: Licensing & SaaS | B26: 6 | U26: =SUMIF(Scoring!K2:K134,A26,Scoring!I2:I134)/SUMIF(Scoring!K2:K134,A26,Scoring!F2:F134) -> 0
A27: Planning & Estimating | B27: 7 | U27: =SUMIF(Scoring!K2:K134,A27,Scoring!I2:I134)/SUMIF(Scoring!K2:K134,A27,Scoring!F2:F134) -> 0
A28: Policy | B28: 5 | U28: =SUMIF(Scoring!K2:K134,A28,Scoring!I2:I134)/SUMIF(Scoring!K2:K134,A28,Scoring!F2:F134) -> 0
A29: Rate Optimization | B29: 6 | U29: =SUMIF(Scoring!K2:K134,A29,Scoring!I2:I134)/SUMIF(Scoring!K2:K134,A29,Scoring!F2:F134) -> 0
A30: Reporting & Analytics | B30: 7 | U30: =SUMIF(Scoring!K2:K134,A30,Scoring!I2:I134)/SUMIF(Scoring!K2:K134,A30,Scoring!F2:F134) -> 0
A31: Unit Economics | B31: 6 | U31: =SUMIF(Scoring!K2:K134,A31,Scoring!I2:I134)/SUMIF(Scoring!K2:K134,A31,Scoring!F2:F134) -> 0
A32: Usage Optimization | B32: 6 | U32: =SUMIF(Scoring!K2:K134,A32,Scoring!I2:I134)/SUMIF(Scoring!K2:K134,A32,Scoring!F2:F134) -> 0
B33: =SUM(Overview!$B$12:$B$32) -> 0

Sheet Scoring
A1: domain | B1: capability | C1: action | D1: serial number | E1: version | F1: weights | G1: formula | H1: scoring | I1: weighted score | J1: _domain | K1: _capability
A2: Manage the FinOps Practice | B2: FinOps Assessment | C2: Define Assessment Scope & Goals | D2: 113 | E2: 1.1.0 | F2: 1 | G2: * Select which teams or groups are in scope for the planned assessments * Select which capabilities/actions are in scope for each group's assessment * Select weights for each included action based on goals of the assessment and importance to the business * Set a preliminary target score for each included action to use for comparison 10*Ceil(x/4) | H2: 0: 0 items completed | I2: =F2*VALUE(LEFT(H2, FIND(":", H2)-1)) -> 0 | J2: Manage the FinOps Practice | K2: FinOps Assessment
C3: Collect Standardized Assessment Inputs | D3: 114 | E3: 1.1.0 | F3: 1 | G3: * Use objective (not subjective) scoring metrics for assessment evaluation * Document how metrics used in the assessment are calculated and state all assumptions * Use the same calculation assumptions and formulas across scopes if possible * List relevant documentation of process and policy as evidentiary support for each score 10*Ceil(x/4) | H3: 0: No items completed | I3: =F3*VALUE(LEFT(H3, FIND(":", H3)-1)) -> 0 | J3: Manage the FinOps Practice | K3: FinOps Assessment
C4: Establish Baselines & Identify Trends | D4: 115 | E4: 1.1.0 | F4: 1 | G4: * Complete an initial assessment for different scopes of the business to establish a baseline * Plot scores over time to track maturity progress for priority scopes * Complete analysis on what contributed to or hindered progress across scopes or different areas of the assessment 10*Ceil(x/3) | H4: 0: No items completed | I4: =F4*VALUE(LEFT(H4, FIND(":", H4)-1)) -> 0 | J4: Manage the FinOps Practice | K4: FinOps Assessment
C5: Prioritize Actions & Publish Roadmap | D5: 116 | E5: 1.1.0 | F5: 1 | G5: 1. Invite subject matter experts (SMEs) and leadership to determine which gaps to address first 2. Determine owners for addressing each of the prioritized gaps 3. Owners will work with relevant teams to scope out how to meet the target score for each gap 4. Work is then scheduled in a roadmap with deadlines that can be tracked at the leadership level | H5: 0: No items completed | I5: =F5*VALUE(LEFT(H5, FIND(":", H5)-1)) -> 0 | J5: Manage the FinOps Practice | K5: FinOps Assessment
C6: Reassess Progress & Update Priorities | D6: 117 | E6: 1.0.0 | F6: 1 | G6: * Schedule a cadence to report progress outcomes to key stakeholders. * Create reporting to show progress on key outcomes across all maturity initiatives. * After successful outcomes are achieved, move on to the next prioritized item in the roadmap. * Periodically reevaluate the gap analysis and priority list based on lessons learned and new business goals. | H6: 0: No items completed | I6: =F6*VALUE(LEFT(H6, FIND(":", H6)-1)) -> 0 | J6: Manage the FinOps Practice | K6: FinOps Assessment
B7: FinOps Education & Enablement | C7: Assess Skills & Training Needs | D7: 097 | E7: 1.0.0 | F7: 1 | H7: 0: Not done | I7: =F7*VALUE(LEFT(H7, FIND(":", H7)-1)) -> 0 | J7: Manage the FinOps Practice | K7: FinOps Education & Enablement
C8: Develop Role-Based Learning Content | D8: 098 | E8: 1.0.0 | F8: 1 | H8: 0: Not done | I8: =F8*VALUE(LEFT(H8, FIND(":", H8)-1)) -> 0 | J8: Manage the FinOps Practice | K8: FinOps Education & Enablement
C9: Offer Certifications & Informal Learning | D9: 099 | E9: 1.0.0 | F9: 1 | H9: 0: Not done | I9: =F9*VALUE(LEFT(H9, FIND(":", H9)-1)) -> 0 | J9: Manage the FinOps Practice | K9: FinOps Education & Enablement
C10: Leverage Vendor Training Resources | D10: 100 | E10: 1.8.0 | F10: 1 | G10: * Define process for reviewing asking for credits from CSPs * Define frequency of review, etc. 10*Ceil(x/2) | H10: 0: No items completed | I10: =F10*VALUE(LEFT(H10, FIND(":", H10)-1)) -> 0 | J10: Manage the FinOps Practice | K10: FinOps Education & Enablement
C11: Track Training Impact & Refresh Content | D11: 101 | E11: 1.0.0 | F11: 1 | H11: 0: Not done | I11: =F11*VALUE(LEFT(H11, FIND(":", H11)-1)) -> 0 | J11: Manage the FinOps Practice | K11: FinOps Education & Enablement
B12: FinOps Practice Operations | C12: Define Org Model & Budget | D12: 091 | E12: 1.8.0 | F12: 1 | H12: 0: Not done | I12: =F12*VALUE(LEFT(H12, FIND(":", H12)-1)) -> 0 | J12: Manage the FinOps Practice | K12: FinOps Practice Operations
C13: Create Implementation Roadmap | D13: 092 | E13: 1.0.0 | F13: 1 | H13: 0: Not done | I13: =F13*VALUE(LEFT(H13, FIND(":", H13)-1)) -> 0 | J13: Manage the FinOps Practice | K13: FinOps Practice Operations
C14: Integrate Cost Data in Workflows | D14: 093 | E14: 1.0.0 | F14: 1 | H14: 0: Not done | I14: =F14*VALUE(LEFT(H14, FIND(":", H14)-1)) -> 0 | J14: Manage the FinOps Practice | K14: FinOps Practice Operations
C15: Publish FinOps KPIs | D15: 094 | E15: 1.0.0 | F15: 1 | H15: 0: Not done | I15: =F15*VALUE(LEFT(H15, FIND(":", H15)-1)) -> 0 | J15: Manage the FinOps Practice | K15: FinOps Practice Operations
C16: Drive Stakeholder Engagement | D16: 095 | E16: 1.0.0 | F16: 1 | H16: 0: Not done | I16: =F16*VALUE(LEFT(H16, FIND(":", H16)-1)) -> 0 | J16: Manage the FinOps Practice | K16: FinOps Practice Operations
C17: Automate Tasks & Review Maturity | D17: 096 | E17: 1.0.0 | F17: 1 | H17: 0: Not done | I17: =F17*VALUE(LEFT(H17, FIND(":", H17)-1)) -> 0 | J17: Manage the FinOps Practice | K17: FinOps Practice Operations
B18: Automation, Tools & Services | C18: Assess Tooling Needs & Criteria | D18: 124 | E18: 1.0.0 | F18: 1 | G18: * Weighted sum Criteria document (score x3), KPI alignment (score x3), Stakeholder count capped at 5 (score x2), Refresh cadence (score x2). Max Raw Score (31) * Criteria formally documented (0=None, 1=Draft, 2=Approved, 3=Versioned+Reviewed) * Criteria explicitly mapped to FinOps KPIs (0=None, 1=Partial, 2=Full) * of FinOps personas involved in criteria definition (0-5) * Criteria review frequency (0=Never, 1=Ad-hoc, 2=Annual, 3=Quarterly+) * Output Range (0 - Max Raw) | H18: 0: Low Maturity (0-9) | I18: =F18*VALUE(LEFT(H18, FIND(":", H18)-1)) -> 0 | J18: Manage the FinOps Practice | K18: Automation, Tools & Services
C19: Evaluate Build vs Buy Options | D19: 125 | E19: 2.1.0 | F19: 1 | G19: * Weighted sum TCO (score x3), Vendor scoring (score x3), Decision document (score x3), Rules established (score x1). Max Raw Score (29) * TCO_Analysis - Total Cost of Ownership analysis performed (0=None, 1=High-level, 2=Detailed, 3=Validated with Finance) * Vendor_Scored - Vendor options scored against criteria (0=None, 1=Informal, 2=Structured scorecard, 3=Multi-stakeholder RFP) * Decision_Doc - Build vs Buy decision formally documented and approved (0=No, 1=Informal note, 2=Formal doc, 3=Exec-approved+reviewed) * Rules_Est - Guiding rules / policy established for future decsions (0=No rules, 1=Draft, 2=Published+Enforced) * Output Range (0 - Max Raw) | H19: 0: Low Maturity. Score Range (0-8) | I19: =F19*VALUE(LEFT(H19, FIND(":", H19)-1)) -> 0 | J19: Manage the FinOps Practice | K19: Automation, Tools & Services
C20: Implement & Configure Tools | D20: 126 | E20: 1.1.0 | F20: 1 | G20: * Weighted sum Env coverage (score x4), Data Integration (score x4), Tag Config (score x2), Config Doc (score x2). Max raw (52) * Env_Coverage - % of cloud environments covered by deployed tools (0=0%, 1<50%, 2=50-79%, 3=80-94%, 4=95-99%, 5=100%) * Data_Integration - Data sources integrated (billing, usage, tags, business context) (0=None, 1=Billing Only, 2=+Usage, 3=+Tags, 4=+Business context, 5=All+Automated) * Tag_Config - Tag/allocation rules configured and enforced tool (0=No, 1=Partial manual, 2=Full manual, 3=Automated enforcement) * Config_Doc - Tool configuration documented and version-controlled (0=No rules, 1=Informal, 2=Documented, 3=Version-controlled+Reviewed) * Output Range (0-52) | H20: 0: Low Maturity. Score Range (0-15) | I20: =F20*VALUE(LEFT(H20, FIND(":", H20)-1)) -> 0 | J20: Manage the FinOps Practice | K20: Automation, Tools & Services
C21: Train Users & Integrate Data | D21: 127 | E21: 1.8.0 | F21: 1 | G21: * Define communication pathways between FinOps and the business * Conduct trainings or create videos * Send out period newsletters * CI/CD governance * Proactive recommendations at deployment 10*Ceil(x/5) | H21: 0: No items completed | I21: =F21*VALUE(LEFT(H21, FIND(":", H21)-1)) -> 0 | J21: Manage the FinOps Practice | K21: Automation, Tools & Services
C22: Monitor Adoption & Iterate Tools | D22: 128 | E22: 1.0.0 | F22: 1 | H22: 0: Not done | I22: =F22*VALUE(LEFT(H22, FIND(":", H22)-1)) -> 0 | J22: Manage the FinOps Practice | K22: Automation, Tools & Services
B23: Intersecting Disciplines | C23: Establish Cross-Team Collab | D23: 129 | E23: 1.1.0 | F23: 1 | G23: 1. Identify key stakeholder teams and key contacts for each (ITAM, SRE, etc.) 2. Document initial thoughts on how this other team may help FinOps goals 3. Document initial thoughts on how the FinOps team may help the other team's goals 4. Reach out to the other team with the initial summary of goals 5. Meet with the other team to better understand how they work | H23: 0: No items completed | I23: =F23*VALUE(LEFT(H23, FIND(":", H23)-1)) -> 0 | J23: Manage the FinOps Practice | K23: Intersecting Disciplines
C24: Align Goals & Data Models | D24: 130 | E24: 1.1.0 | F24: 1 | G24: * Align on new shared goals that will enhance both teams achievements * Determine what data is shared across teams to establish a single source of truth * Identify and agree on tasks that will lead to accomplishing shared goals * Determine which teams have capacity to work on goal tasks periodically * Incorporate tasks into team capacity planning and dependency workflows 10*Ceil(x/5) | H24: 0: No items completed | I24: =F24*VALUE(LEFT(H24, FIND(":", H24)-1)) -> 0 | J24: Manage the FinOps Practice | K24: Intersecting Disciplines
C25: Share Reporting & Definitions | D25: 131 | E25: 1.1.0 | F25: 1 | G25: * Agree on definitions of shared concepts across teams to reduce confusion * Adjust reporting so shared metrics are consistent and from the same source, even if multiple dashboards exist * Regularly align on interpretation of shared metrics to plan next steps and report those to leadership 10*Ceil(x/3) | H25: 0: No items completed | I25: =F25*VALUE(LEFT(H25, FIND(":", H25)-1)) -> 0 | J25: Manage the FinOps Practice | K25: Intersecting Disciplines
C26: Provide Technology Metrics to Teams | D26: 132 | E26: 1.1.0 | F26: 1 | G26: * Share relevant data already maintained and tracked by FinOps * Share metric reporting and the calculations behind FinOps created metrics * Create new metrics from FinOps and other data based on needs of allied teams 10*Ceil(x/3) | H26: 0: No items completed | I26: =F26*VALUE(LEFT(H26, FIND(":", H26)-1)) -> 0 | J26: Manage the FinOps Practice | K26: Intersecting Disciplines
C27: Coordinate Policy Changes Broadly | D27: 133 | E27: 1.1.0 | F27: 1 | G27: 1. Document new policies as a result of cross-functional collaboration goals 2. Broad policy changes are accepted by governing and stakeholder teams 3. Communication is distributed by all governing teams using shared language 4. Change management procedures are followed for updated policy implementation 10*Ceil(x/4) | H27: 0: No items completed | I27: =F27*VALUE(LEFT(H27, FIND(":", H27)-1)) -> 0 | J27: Manage the FinOps Practice | K27: Intersecting Disciplines
C28: Drive Adoption & Resolve Conflicts | D28: 134 | E28: 1.1.0 | F28: 1 | G28: * Come up with shared responses as allied teams to external conflicts * Resolve internal conflicts before deciding on the next steps needed to reach shared goals * Communication to external teams or leaders includes the full story of how allied teams achieve goals together 10*Ceil(x/3) | H28: 0: No items completed | I28: =F28*VALUE(LEFT(H28, FIND(":", H28)-1)) -> 0 | J28: Manage the FinOps Practice | K28: Intersecting Disciplines
B29: Invoicing & Chargeback | C29: Map Invoices to Allocation Model | D29: 107 | E29: 1.0.0 | F29: 1 | H29: 0: Not done | I29: =F29*VALUE(LEFT(H29, FIND(":", H29)-1)) -> 0 | J29: Manage the FinOps Practice | K29: Invoicing & Chargeback
C30: Reconcile Rates & Track Completion | D30: 108 | E30: 1.0.0 | F30: 1 | H30: 0: Not done | I30: =F30*VALUE(LEFT(H30, FIND(":", H30)-1)) -> 0 | J30: Manage the FinOps Practice | K30: Invoicing & Chargeback
C31: Design Chargeback with Finance | D31: 109 | E31: 1.8.0 | F31: 1 | H31: 0: Not done | I31: =F31*VALUE(LEFT(H31, FIND(":", H31)-1)) -> 0 | J31: Manage the FinOps Practice | K31: Invoicing & Chargeback
C32: Automate Chargeback Data Flows | D32: 110 | E32: 1.0.0 | F32: 1 | H32: 0: Not done | I32: =F32*VALUE(LEFT(H32, FIND(":", H32)-1)) -> 0 | J32: Manage the FinOps Practice | K32: Invoicing & Chargeback
C33: Distribute Reports & Track Accuracy | D33: 111 | E33: 1.0.0 | F33: 1 | H33: 0: Not done | I33: =F33*VALUE(LEFT(H33, FIND(":", H33)-1)) -> 0 | J33: Manage the FinOps Practice | K33: Invoicing & Chargeback
C34: Resolve Variances & Increase Coverage | D34: 112 | E34: 1.8.0 | F34: 1 | H34: 0: Not done | I34: =F34*VALUE(LEFT(H34, FIND(":", H34)-1)) -> 0 | J34: Manage the FinOps Practice | K34: Invoicing & Chargeback
B35: Executive Strategy Alignment | C35: Establish Executive Sponsorship | D35: 136 | E35: 1.1.0 | F35: 1 | H35: 0: No executive sponsor identified | I35: =F35*VALUE(LEFT(H35, FIND(":", H35)-1)) -> 0 | J35: Manage the FinOps Practice | K35: Executive Strategy Alignment
C36: Define Decision Rights & Guardrails | D36: 137 | E36: 1.0.0 | F36: 1 | G36: * Document decision rights and approval authority for technology spend * Define and publish spend guardrails with named owners * Establish escalation path for spend exceptions 10*Ceil(x/3) | H36: 0: No items completed | I36: =F36*VALUE(LEFT(H36, FIND(":", H36)-1)) -> 0 | J36: Manage the FinOps Practice | K36: Executive Strategy Alignment
C37: Build Multi-Year Investment Forecast | D37: 138 | E37: 1.0.0 | F37: 1 | G37: * Inventory vendor commitments across technology categories (cloud, SaaS, data center, AI) * Create a multi-year forecast incorporating renewal timelines and growth projections * Incorporate transition and modernization costs into the investment plan 10*Ceil(x/3) | H37: 0: No items completed | I37: =F37*VALUE(LEFT(H37, FIND(":", H37)-1)) -> 0 | J37: Manage the FinOps Practice | K37: Executive Strategy Alignment
C38: Establish Decision Support Cadence | D38: 139 | E38: 1.0.0 | F38: 1 | G38: * Define a regular review cadence for technology investment decisions * Deliver cost and outcome comparisons for competing initiatives at reviews * Track and report action follow-through from investment decisions 10*Ceil(x/3) | H38: 0: No items completed | I38: =F38*VALUE(LEFT(H38, FIND(":", H38)-1)) -> 0 | J38: Manage the FinOps Practice | K38: Executive Strategy Alignment
A39: Usage & Cost | B39: Architecting & Workload Placement | C39: Establish Architecture Review Process | D39: 061 | E39: 1.8.0 | F39: 1 | H39: 0: Does not exist | I39: =F39*VALUE(LEFT(H39, FIND(":", H39)-1)) -> 0 | J39: Usage & Cost | K39: Architecting & Workload Placement
C40: Assess Workloads for Modernization | D40: 062 | E40: 1.8.0 | F40: 1 | G40: * Define process to address notifications from CSPs * Define cadence for review * Define exception criteria * Define thresholds to change * Combine with architecture analysis for SP & RIs 10*Ceil(x/5) | H40: 0: No items completed | I40: =F40*VALUE(LEFT(H40, FIND(":", H40)-1)) -> 0 | J40: Usage & Cost | K40: Architecting & Workload Placement
...
